Workbook
Name Slicer_Channel_Name: #N/A
Name Slicer_Channel_Name1: #N/A
Name Slicer_Delivered_Count: #N/A
Name Slicer_Delivered_Count1: #N/A
Name Slicer_Delivered_Revenue: #N/A
Name Slicer_Delivered_Revenue1: #N/A
Name Slicer_RTO_Count: #N/A
Name Slicer_RTO_Count1: #N/A
Name Slicer_RTO_Revenue: #N/A
Name Slicer_RTO_Revenue1: #N/A
Name Slicer_Total_order_count: #N/A
Name Slicer_Total_order_count1: #N/A
Name Slicer_Total_Order_Revenue: #N/A
Name Slicer_Total_Order_Revenue1: #N/A

Sheet Topsheet
G1: TCS!D2
B2: Sales summary for the month of Mid Apr-2026 | G2: Fashion_GOFPL_042026_Sales_01-15
B4: {="Common Name :- "&INDIRECT(G1)} -> Common Name :- Fashion_GOFPL_042026_Sales_01-15
B6: Order Status in Mid Apr-26 Including Prev. Month | C6: Mid Apr'26
C7: Order Count | D7: TCS Amount | E7: Sales
B8: Delivered | C8: =COUNTIFS(nykaa!F:F,Topsheet!$G$2,nykaa!AT:AT,Topsheet!B8) -> 56 | D8: =SUMIFS(nykaa!AS:AS,nykaa!F:F,Topsheet!$G$2,nykaa!AT:AT,Topsheet!B8) -> 416.05222 | E8: =D8/0.5% -> 83210.445
B9: Return | C9: =COUNTIFS(nykaa!F:F,Topsheet!$G$2,nykaa!AT:AT,Topsheet!B9) -> 10 | D9: =SUMIFS(nykaa!AS:AS,nykaa!F:F,Topsheet!$G$2,nykaa!AT:AT,Topsheet!B9) -> 0 | E9: =D9/0.5% -> 0
B10: Not Shipped | C10: =COUNTIFS(nykaa!F:F,Topsheet!$G$2,nykaa!AT:AT,Topsheet!B10) -> 9 | D10: =SUMIFS(nykaa!AS:AS,nykaa!F:F,Topsheet!$G$2,nykaa!AT:AT,Topsheet!B10) -> 0 | E10: =D10/0.5% -> 0
B11: Cancelled | C11: =COUNTIFS(nykaa!F:F,Topsheet!$G$2,nykaa!AT:AT,Topsheet!B11) -> 4 | D11: =SUMIFS(nykaa!AS:AS,nykaa!F:F,Topsheet!$G$2,nykaa!AT:AT,Topsheet!B11) -> 0 | E11: =D11/0.5% -> 0
B12: Lost | C12: =COUNTIFS(nykaa!F:F,Topsheet!$G$2,nykaa!AT:AT,Topsheet!B12) -> 0 | D12: =SUMIFS(nykaa!AS:AS,nykaa!F:F,Topsheet!$G$2,nykaa!AT:AT,Topsheet!B12) -> 0 | E12: =D12/0.5% -> 0
B13: RTO | C13: =COUNTIFS(nykaa!F:F,Topsheet!$G$2,nykaa!AT:AT,Topsheet!B13) -> 2 | D13: =SUMIFS(nykaa!AS:AS,nykaa!F:F,Topsheet!$G$2,nykaa!AT:AT,Topsheet!B13) -> 0 | E13: =D13/0.5% -> 0
B14: Shipped | C14: =COUNTIFS(nykaa!F:F,Topsheet!$G$2,nykaa!AT:AT,Topsheet!B14) -> 12 | D14: =SUMIFS(nykaa!AS:AS,nykaa!F:F,Topsheet!$G$2,nykaa!AT:AT,Topsheet!B14) -> 0 | E14: =D14/0.5% -> 0
B15: Total (Sheet ''Mid Apr_Orders") | C15: =SUM(C8:C14) -> 93 | D15: =SUM(D8:D14) -> 416.05222 | E15: =D15/0.5% -> 83210.445
B18: Final Status Deliverd & Lost - Prev. Final Status Delivered to returns = Sales | C18: Order Count | D18: Sales | E18: Diff
B20: Delivered | C20: =COUNTIFS(nykaa!F:F,Topsheet!$G$2,nykaa!AT:AT,Topsheet!B20) -> 56 | D20: =SUMIFS(nykaa!X:X,nykaa!F:F,Topsheet!$G$2,nykaa!AT:AT,Topsheet!B20) -> 83210.445 | E20: =D20-E8 -> 0
B21: Lost | C21: =COUNTIFS(nykaa!F:F,Topsheet!$G$2,nykaa!AT:AT,Topsheet!B21) -> 0 | D21: =SUMIFS(nykaa!X:X,nykaa!F:F,Topsheet!$G$2,nykaa!AT:AT,Topsheet!B21) -> 0 | E21: =D21-E12 -> 0
B22: Return | C22: =COUNTIFS(nykaa!F:F,Topsheet!$G$2,nykaa!AT:AT,Topsheet!B22) -> 10 | D22: =-SUMIFS(nykaa!X:X,nykaa!F:F,Topsheet!$G$2,nykaa!AU:AU,"Delivered") -> 0 | E22: =D22-E9 -> 0
B23: Total Net Sales | D23: =SUM(D20:D22) -> 83210.445 | E23: =D23-E15 -> 0

Sheet TCS
A1: brand | B1: parent_vendor_name | C1: Common Name | D1: Other Name | E1: Sum of TCS | F1: Sum of base_value
A2: Chelvet | B2: GOTCHA FASHIONS PVT LTD_DL | C2: GOTCHA FASHIONS PRIVATE LIMITED-NF Mid Apr-26 Sales | D2: Fashion_GOFPL_042026_Sales_01-15 | E2: 387.71324 | F2: 77542.648

Sheet nykaa
A1: Period | B1: Month | C1: parent_vendor_code | D1: parent_vendor_name | E1: Common Name | F1: Other Name | G1: nykaa_orderno | H1: externorderno | I1: eretail_orderno | J1: product_sku | K1: product_name | L1: brand | M1: hsn_code | N1: mrp_per_unit | O1: dp_per_unit | P1: sp_per_unit | Q1: dp_per_unit_brand | R1: DP Nykaa Funded | S1: DP Brand Funded | T1: SP Coupon Nykaa Funded | U1: SP Brand Funded | V1: NSV= Net Sale Value | W1: taxable_amount | X1: base_value | Y1: tax_amount | Z1: tax_percent | AA1: cgst | AB1: sgst | AC1: ugst | AD1: igst | AE1: order_shipping_city | AF1: order_shipping_state | AG1: order_type | AH1: Child Vendor GST | AI1: invoiceno | AJ1: tracking_no | AK1: return_awb | AL1: order_date | AM1: ship_date | AN1: delivery_date | AO1: Quantity | AP1: Rule Name | AQ1: Yes or No | AR1: CountIF | AS1: TCS | AT1: FinalStatus | AU1: Previous Final Status
A2: APRIL_1_to_15_Orders | B2: 4 | C2: GOFPL | D2: GOTCHA FASHIONS PVT LTD_DL | E2: GOTCHA FASHIONS PRIVATE LIMITED-NF Mid Apr-26 Sales | F2: Fashion_GOFPL_042026_Sales_01-15 | G2: NYK-38112834-8327464 | H2: NYK-38112834-8327464-2-1 | I2: NYKF42123624 | J2: CHELV00001661 | K2: Chelvet Purple Satin Shirt With Pyjama (M) | L2: Chelvet | M2: 62082200 | N2: 2999 | O2: 2999 | P2: 2922.58 | Q2: 2999 | R2: 0 | S2: 0 | T2: 76.419998 | U2: 0 | V2: 2999 | W2: 2999 | X2: 2541.525 | Y2: 457.475 | Z2: 18 | AA2: 0 | AB2: 0 | AC2: 0 | AD2: 457.475 | AE2: Raipur | AF2: Chhattisgarh | AG2: COD | AH2: 09AALCG0172B1ZW | AI2: GOFPL2709100150 | AJ2: 28449601682033 | AL2: 46117.474 | AM2: 46118.618 | AN2: 46122.614 | AO2: 1 | AP2: Dynamic RB Paltform wide:Extra 10% off upto 270 on 1700 : 3 PV | AQ2: Yes | AR2: 3 | AS2: 12.707625 | AT2: Delivered
A3: APRIL_1_to_15_Orders | B3: 4 | C3: GOFPL | D3: GOTCHA FASHIONS PVT LTD_DL | E3: GOTCHA FASHIONS PRIVATE LIMITED-NF Mid Apr-26 Sales | F3: Fashion_GOFPL_042026_Sales_01-15 | G3: NYK-37984287-4482735 | H3: NYK-37984287-4482735-1-1 | I3: NYKF41978771 | J3: CHELV00001011 | K3: Chelvet Non-Wired Seamless Finish Plunge Bra (32B) | L3: Chelvet | M3: 62121000 | N3: 1849 | O3: 1295 | P3: 1229.34 | Q3: 1295 | R3: 0 | S3: 554 | T3: 65.660004 | U3: 0 | V3: 1295 | W3: 1295 | X3: 1233.333 | Y3: 61.667 | Z3: 5 | AA3: 0 | AB3: 0 | AC3: 0 | AD3: 61.667 | AE3: Faridabad | AF3: Haryana | AG3: Prepaid | AH3: 07AALCG0172B1Z0 | AL3: 46113.494 | AO3: 1 | AP3: Dynamic IOC1 & 2: Extra 10% off upto Rs 250 on 2000 | AQ3: Yes | AR3: 1 | AS3: 0 | AT3: Not Shipped
A4: APRIL_1_to_15_Orders | B4: 4 | C4: GOFPL | D4: GOTCHA FASHIONS PVT LTD_DL | E4: GOTCHA FASHIONS PRIVATE LIMITED-NF Mid Apr-26 Sales | F4: Fashion_GOFPL_042026_Sales_01-15 | G4: NYK-38130788-0594892 | H4: NYK-38130788-0594892-1-1 | I4: NYKF42144141 | J4: CHELV00002258 | K4: Chelvet Satin Lace Midi Dress with Robe (M) | L4: Chelvet | M4: 61091000 | N4: 2750 | O4: 1760 | P4: 1760 | Q4: 1760 | R4: 0 | S4: 990 | T4: 0 | U4: 0 | V4: 1760 | W4: 1760 | X4: 1676.19 | Y4: 83.81 | Z4: 5 | AA4: 0 | AB4: 0 | AC4: 0 | AD4: 83.81 | AE4: Bangalore | AF4: Karnataka | AG4: COD | AH4: 09AALCG0172B1ZW | AL4: 46117.847 | AO4: 1 | AQ4: Yes | AR4: 3 | AS4: 0 | AT4: Cancelled
A5: APRIL_1_to_15_Orders | B5: 4 | C5: GOFPL | D5: GOTCHA FASHIONS PVT LTD_DL | E5: GOTCHA FASHIONS PRIVATE LIMITED-NF Mid Apr-26 Sales | F5: Fashion_GOFPL_042026_Sales_01-15 | G5: NYK-37999926-8439694 | H5: NYK-37999926-8439694-2-1 | I5: NYKF41996559 | J5: CHELV00001423 | K5: Chelvet Women Pink Velvet Solid Jacket with Pyjama (L) | L5: Chelvet | M5: 61083100 | N5: 5099 | O5: 3213 | P5: 3213 | Q5: 3213 | R5: 0 | S5: 1886 | T5: 0 | U5: 0 | V5: 3213 | W5: 3213 | X5: 2722.881 | Y5: 490.119 | Z5: 18 | AA5: 0 | AB5: 0 | AC5: 0 | AD5: 490.119 | AE5: Mumbai | AF5: Maharashtra | AG5: Prepaid | AH5: 09AALCG0172B1ZW | AI5: GOFPL2709100137 | AJ5: 28449609598716 | AL5: 46113.887 | AM5: 46114.606 | AN5: 46118.641 | AO5: 1 | AQ5: Yes | AR5: 1 | AS5: 13.614405 | AT5: Delivered
A6: APRIL_1_to_15_Orders | B6: 4 | C6: GOFPL | D6: GOTCHA FASHIONS PVT LTD_DL | E6: GOTCHA FASHIONS PRIVATE LIMITED-NF Mid Apr-26 Sales | F6: Fashion_GOFPL_042026_Sales_01-15 | G6: NYK-38430708-8077330 | H6: NYK-38430708-8077330-1-1 | I6: NYKF42488214 | J6: CHELV00002421 | K6: Chelvet Red Non-Padded Non-Wired Lace Bra (36D) | L6: Chelvet | M6: 62121000 | N6: 1499 | O6: 900 | P6: 900 | Q6: 900 | R6: 0 | S6: 599 | T6: 0 | U6: 0 | V6: 900 | W6: 900 | X6: 857.143 | Y6: 42.857 | Z6: 5 | AA6: 0 | AB6: 0 | AC6: 0 | AD6: 42.857 | AE6: Bhubaneswar | AF6: Orissa | AG6: Prepaid | AH6: 09AALCG0172B1ZW | AI6: GOFPL2709100167 | AJ6: 88364570486 | AL6: 46125.92 | AM6: 46127.661 | AO6: 1 | AQ6: Yes | AR6: 1 | AS6: 0 | AT6: Shipped
A7: APRIL_1_to_15_Orders | B7: 4 | C7: GOFPL | D7: GOTCHA FASHIONS PVT LTD_DL | E7: GOTCHA FASHIONS PRIVATE LIMITED-NF Mid Apr-26 Sales | F7: Fashion_GOFPL_042026_Sales_01-15 | G7: NYK-38166264-2307271 | H7: NYK-38166264-2307271-1-1 | I7: NYKF42184995 | J7: CHELV00000924 | K7: Chelvet Underwired Lightly Padded Demi Cup Bra (32C) | L7: Chelvet | M7: 62121000 | N7: 1699 | O7: 1394 | P7: 1394 | Q7: 1394 | R7: 0 | S7: 305 | T7: 0 | U7: 0 | V7: 1394 | W7: 1394 | X7: 1327.619 | Y7: 66.381 | Z7: 5 | AA7: 0 | AB7: 0 | AC7: 0 | AD7: 66.381 | AE7: Cochin | AF7: Kerala | AG7: COD | AH7: 07AALCG0172B1Z0 | AI7: GOFPL2707100604 | AJ7: 28449601872304 | AL7: 46118.909 | AM7: 46121.496 | AN7: 46125.605 | AO7: 1 | AQ7: Yes | AR7: 1 | AS7: 6.638095 | AT7: Delivered
A8: APRIL_1_to_15_Orders | B8: 4 | C8: GOFPL | D8: GOTCHA FASHIONS PVT LTD_DL | E8: GOTCHA FASHIONS PRIVATE LIMITED-NF Mid Apr-26 Sales | F8: Fashion_GOFPL_042026_Sales_01-15 | G8: NYK-38149484-7129408 | H8: NYK-38149484-7129408-1-1 | I8: NYKF42165824 | J8: CHELV00000478 | K8: Chelvet Women Black Medium Coverage Non-Wired Lightly Padded Everyday Bra (36C) | L8: Chelvet | M8: 62121000 | N8: 1749 | O8: 1400 | P8: 1352.42 | Q8: 1400 | R8: 0 | S8: 349 | T8: 47.580002 | U8: 0 | V8: 1400 | W8: 1400 | X8: 1333.333 | Y8: 66.667 | Z8: 5 | AA8: 0 | AB8: 0 | AC8: 0 | AD8: 66.667 | AE8: Hyderabad | AF8: Telangana | AG8: Prepaid | AH8: 07AALCG0172B1Z0 | AL8: 46118.501 | AO8: 1 | AQ8: Yes | AR8: 2 | AS8: 0 | AT8: Not Shipped
A9: APRIL_1_to_15_Orders | B9: 4 | C9: GOFPL | D9: GOTCHA FASHIONS PVT LTD_DL | E9: GOTCHA FASHIONS PRIVATE LIMITED-NF Mid Apr-26 Sales | F9: Fashion_GOFPL_042026_Sales_01-15 | G9: NYK-38465841-6352996 | H9: NYK-38465841-6352996-1-1 | I9: NYKF42528705 | J9: CHELV00001573 | K9: Chelvet Women Light Pink Seamless Padded Pull On Bra (L) | L9: Chelvet | M9: 62121000 | N9: 2540 | O9: 1499 | P9: 1499 | Q9: 1499 | R9: 0 | S9: 1041 | T9: 0 | U9: 0 | V9: 1499 | W9: 1499 | X9: 1427.619 | Y9: 71.381 | Z9: 5 | AA9: 35.691 | AB9: 35.691 | AC9: 0 | AD9: 0 | AE9: Agra | AF9: Uttar Pradesh | AG9: Prepaid | AH9: 09AALCG0172B1ZW | AI9: GOFPL2709100169 | AJ9: SF2188751540NYK | AL9: 46126.826 | AM9: 46127.558 | AO9: 1 | AQ9: Yes | AR9: 1 | AS9: 0 | AT9: Shipped
A10: APRIL_1_to_15_Orders | B10: 4 | C10: GOFPL | D10: GOTCHA FASHIONS PVT LTD_DL | E10: GOTCHA FASHIONS PRIVATE LIMITED-NF Mid Apr-26 Sales | F10: Fashion_GOFPL_042026_Sales_01-15 | G10: NYK-38129696-8729519 | H10: NYK-38129696-8729519-3-1 | I10: NYKF42142936 | J10: CHELV00002403 | K10: Chelvet Nude Non-Padded Non-Wired Lace Bra (32D) | L10: Chelvet | M10: 62121000 | N10: 1499 | O10: 900 | P10: 852.13 | Q10: 900 | R10: 0 | S10: 599 | T10: 47.869999 | U10: 0 | V10: 900 | W10: 900 | X10: 857.143 | Y10: 42.857 | Z10: 5 | AA10: 0 | AB10: 0 | AC10: 0 | AD10: 42.857 | AE10: Bangalore | AF10: Karnataka | AG10: COD | AH10: 09AALCG0172B1ZW | AI10: GOFPL2709100145 | AJ10: 28449601680854 | AL10: 46117.826 | AM10: 46119.685 | AN10: 46125.888 | AO10: 1 | AQ10: Yes | AR10: 1 | AS10: 4.285715 | AT10: Delivered
A11: APRIL_1_to_15_Orders | B11: 4 | C11: GOFPL | D11: GOTCHA FASHIONS PVT LTD_DL | E11: GOTCHA FASHIONS PRIVATE LIMITED-NF Mid Apr-26 Sales | F11: Fashion_GOFPL_042026_Sales_01-15 | G11: NYK-38307031-8860236 | H11: NYK-38307031-8860236-1-1 | I11: NYKF42345044 | J11: CHELV00001355 | K11: Chelvet Women Pink Satin Solid Nightdress with Robe and Belt (M) | L11: Chelvet | M11: 62082200 | N11: 5699 | O11: 3819 | P11: 3539 | Q11: 3819 | R11: 0 | S11: 1880 | T11: 280 | U11: 0 | V11: 3819 | W11: 3819 | X11: 3236.441 | Y11: 582.559 | Z11: 18 | AA11: 0 | AB11: 0 | AC11: 0 | AD11: 582.559 | AE11: Chennai | AF11: Tamil Nadu | AG11: Prepaid | AH11: 09AALCG0172B1ZW | AI11: GOFPL2709100163 | AJ11: 88364307043 | AL11: 46122.92 | AM11: 46127.661 | AO11: 1 | AQ11: Yes | AR11: 1 | AS11: 0 | AT11: Shipped
A12: APRIL_1_to_15_Orders | B12: 4 | C12: GOFPL | D12: GOTCHA FASHIONS PVT LTD_DL | E12: GOTCHA FASHIONS PRIVATE LIMITED-NF Mid Apr-26 Sales | F12: Fashion_GOFPL_042026_Sales_01-15 | G12: NYK-38283607-0081774 | H12: NYK-38283607-0081774-1-1 | I12: NYKF42318257 | J12: CHELV00002248 | K12: Chelvet Floral Strappy Nightdress and Full Sleeve Robe (M) | L12: Chelvet | M12: 61091000 | N12: 4950 | O12: 3168 | P12: 2888 | Q12: 3168 | R12: 0 | S12: 1782 | T12: 280 | U12: 0 | V12: 3168 | W12: 3168 | X12: 2684.746 | Y12: 483.254 | Z12: 18 | AA12: 0 | AB12: 0 | AC12: 0 | AD12: 483.254 | AE12: Bangalore | AF12: Karnataka | AG12: COD | AH12: 09AALCG0172B1ZW | AI12: GOFPL2709100162 | AJ12: 59695181302 | AL12: 46122.471 | AM12: 46127.661 | AO12: 1 | AQ12: Yes | AR12: 1 | AS12: 0 | AT12: Shipped
A13: APRIL_1_to_15_Orders | B13: 4 | C13: GOFPL | D13: GOTCHA FASHIONS PVT LTD_DL | E13: GOTCHA FASHIONS PRIVATE LIMITED-NF Mid Apr-26 Sales | F13: Fashion_GOFPL_042026_Sales_01-15 | G13: NYK-38310048-3098293 | H13: NYK-38310048-3098293-1-1 | I13: NYKF42348508 | J13: CHELV00001169 | K13: Chelvet Non-Wired Medium Coverage T-Shirt Bra (34D) | L13: Chelvet | M13: 62121000 | N13: 1849 | O13: 1054 | P13: 1054 | Q13: 1054 | R13: 0 | S13: 795 | T13: 0 | U13: 0 | V13: 1054 | W13: 1054 | X13: 1003.81 | Y13: 50.19 | Z13: 5 | AA13: 0 | AB13: 0 | AC13: 0 | AD13: 50.19 | AE13: Kolkata | AF13: West Bengal | AG13: Prepaid | AH13: 07AALCG0172B1Z0 | AI13: GOFPL2707100608 | AJ13: 88364286872 | AL13: 46122.969 | AM13: 46123.685 | AN13: 46124.759 | AO13: 1 | AQ13: Yes | AR13: 1 | AS13: 5.01905 | AT13: Delivered
A14: APRIL_1_to_15_Orders | B14: 4 | C14: GOFPL | D14: GOTCHA FASHIONS PVT LTD_DL | E14: GOTCHA FASHIONS PRIVATE LIMITED-NF Mid Apr-26 Sales | F14: Fashion_GOFPL_042026_Sales_01-15 | G14: NYK-38112834-8327464 | H14: NYK-38112834-8327464-2-1 | I14: NYKF42123624 | J14: CHELV00001673 | K14: Chelvet White Satin Shirt With Pyjama (M) | L14: Chelvet | M14: 62082200 | N14: 2999 | O14: 2999 | P14: 2922.58 | Q14: 2999 | R14: 0 | S14: 0 | T14: 76.419998 | U14: 0 | V14: 2999 | W14: 2999 | X14: 2541.525 | Y14: 457.475 | Z14: 18 | AA14: 0 | AB14: 0 | AC14: 0 | AD14: 457.475 | AE14: Raipur | AF14: Chhattisgarh | AG14: COD | AH14: 09AALCG0172B1ZW | AI14: GOFPL2709100150 | AJ14: 28449601682033 | AL14: 46117.474 | AM14: 46118.618 | AN14: 46122.614 | AO14: 1 | AP14: Dynamic RB Paltform wide:Extra 10% off upto 270 on 1700 : 3 PV | AQ14: Yes | AR14: 3 | AS14: 12.707625 | AT14: Delivered
A15: APRIL_1_to_15_Orders | B15: 4 | C15: GOFPL | D15: GOTCHA FASHIONS PVT LTD_DL | E15: GOTCHA FASHIONS PRIVATE LIMITED-NF Mid Apr-26 Sales | F15: Fashion_GOFPL_042026_Sales_01-15 | G15: NYK-38274618-4377193 | H15: NYK-38274618-4377193-1-1 | I15: NYKF42308192 | J15: CHELV00001109 | K15: Chelvet Push-Up Non wired Medium Coverage Bra (38D) | L15: Chelvet | M15: 62121000 | N15: 1749 | O15: 1050 | P15: 1050 | Q15: 1050 | R15: 0 | S15: 699 | T15: 0 | U15: 0 | V15: 1050 | W15: 1050 | X15: 1000 | Y15: 50 | Z15: 5 | AA15: 0 | AB15: 0 | AC15: 0 | AD15: 50 | AE15: Aligarh | AF15: Uttar Pradesh | AG15: COD | AH15: 07AALCG0172B1Z0 | AI15: GOFPL2707100606 | AJ15: NKFC0000459950 | AL15: 46122.058 | AM15: 46122.548 | AN15: 46124.73 | AO15: 1 | AQ15: Yes | AR15: 3 | AS15: 5 | AT15: Delivered
A16: APRIL_1_to_15_Orders | B16: 4 | C16: GOFPL | D16: GOTCHA FASHIONS PVT LTD_DL | E16: GOTCHA FASHIONS PRIVATE LIMITED-NF Mid Apr-26 Sales | F16: Fashion_GOFPL_042026_Sales_01-15 | G16: NYK-38416538-3363882 | H16: NYK-38416538-3363882-1-1 | I16: NYKF42472137 | J16: CHELV00000062 | K16: Chelvet Solid Lightly Padded Half Coverage Plunge Bra (36C) | L16: Chelvet | M16: 61089100 | N16: 1499 | O16: 1050 | P16: 892.5 | Q16: 1050 | R16: 0 | S16: 449 | T16: 157.5 | U16: 0 | V16: 1050 | W16: 1050 | X16: 1000 | Y16: 50 | Z16: 5 | AA16: 0 | AB16: 0 | AC16: 0 | AD16: 50 | AE16: Bangalore | AF16: Karnataka | AG16: Prepaid | AH16: 07AALCG0172B1Z0 | AI16: GOFPL2707100616 | AJ16: 88364558645 | AL16: 46125.634 | AM16: 46126.637 | AO16: 1 | AQ16: Yes | AR16: 1 | AS16: 0 | AT16: Shipped
A17: APRIL_1_to_15_Orders | B17: 4 | C17: GOFPL | D17: GOTCHA FASHIONS PVT LTD_DL | E17: GOTCHA FASHIONS PRIVATE LIMITED-NF Mid Apr-26 Sales | F17: Fashion_GOFPL_042026_Sales_01-15 | G17: NYK-38046081-9372889 | H17: NYK-38046081-9372889-2-1 | I17: NYKF42047886 | J17: CHELV00002055 | K17: Chelvet Women Padded Non-Wired Lace Black Bralette (36D) | L17: Chelvet | M17: 62121000 | N17: 2299 | O17: 1495 | P17: 1407.22 | Q17: 1495 | R17: 0 | S17: 804 | T17: 87.779999 | U17: 0 | V17: 1495 | W17: 1495 | X17: 1423.81 | Y17: 71.19 | Z17: 5 | AA17: 0 | AB17: 0 | AC17: 0 | AD17: 71.19 | AE17: Siliguri | AF17: West Bengal | AG17: COD | AH17: 09AALCG0172B1ZW | AI17: GOFPL2709100141 | AJ17: 28449601497760 | AL17: 46115.518 | AM17: 46116.633 | AN17: 46119.613 | AO17: 1 | AQ17: Yes | AR17: 1 | AS17: 7.11905 | AT17: Delivered
A18: APRIL_1_to_15_Orders | B18: 4 | C18: GOFPL | D18: GOTCHA FASHIONS PVT LTD_DL | E18: GOTCHA FASHIONS PRIVATE LIMITED-NF Mid Apr-26 Sales | F18: Fashion_GOFPL_042026_Sales_01-15 | G18: NYK-38106346-6283082 | H18: NYK-38106346-6283082-2-1 | I18: NYKF42116285 | J18: CHELV00001107 | K18: Chelvet Push-Up Non wired Medium Coverage Bra (38B) | L18: Chelvet | M18: 62121000 | N18: 1749 | O18: 1050 | P18: 1050 | Q18: 1050 | R18: 0 | S18: 699 | T18: 0 | U18: 0 | V18: 1050 | W18: 1050 | X18: 1000 | Y18: 50 | Z18: 5 | AA18: 0 | AB18: 0 | AC18: 0 | AD18: 50 | AE18: Faridabad | AF18: Haryana | AG18: Prepaid | AH18: 07AALCG0172B1Z0 | AI18: GOFPL2707100599 | AJ18: SF2188733487NYK | AL18: 46117.103 | AM18: 46119.621 | AN18: 46120.909 | AO18: 1 | AQ18: Yes | AR18: 1 | AS18: 5 | AT18: Delivered
A19: APRIL_1_to_15_Orders | B19: 4 | C19: GOFPL | D19: GOTCHA FASHIONS PVT LTD_DL | E19: GOTCHA FASHIONS PRIVATE LIMITED-NF Mid Apr-26 Sales | F19: Fashion_GOFPL_042026_Sales_01-15 | G19: NYK-38271552-8059338 | H19: NYK-38271552-8059338-1-1 | I19: NYKF42304631 | J19: CHELV00000267 | K19: Chelvet Peach Solid Workout Bra (34D) | L19: Chelvet | M19: 62121000 | N19: 1599 | O19: 1056 | P19: 1056 | Q19: 1056 | R19: 0 | S19: 543 | T19: 0 | U19: 0 | V19: 1056 | W19: 1056 | X19: 1005.714 | Y19: 50.286 | Z19: 5 | AA19: 0 | AB19: 0 | AC19: 0 | AD19: 50.286 | AE19: Godhra | AF19: Gujarat | AG19: COD | AH19: 07AALCG0172B1Z0 | AI19: GOFPL2707100605 | AJ19: 28449601942901 | AL19: 46121.984 | AM19: 46122.489 | AO19: 1 | AQ19: Yes | AR19: 1 | AS19: 0 | AT19: RTO
A20: APRIL_1_to_15_Orders | B20: 4 | C20: GOFPL | D20: GOTCHA FASHIONS PVT LTD_DL | E20: GOTCHA FASHIONS PRIVATE LIMITED-NF Mid Apr-26 Sales | F20: Fashion_GOFPL_042026_Sales_01-15 | G20: NYK-37978882-9341965 | H20: NYK-37978882-9341965-1-1 | I20: NYKF41973053 | J20: CHELV00000919 | K20: Chelvet Underwired Lightly Padded Demi Cup Bra (36D) | L20: Chelvet | M20: 62121000 | N20: 1699 | O20: 1394 | P20: 1394 | Q20: 1394 | R20: 0 | S20: 305 | T20: 0 | U20: 0 | V20: 1394 | W20: 1394 | X20: 1327.619 | Y20: 66.381 | Z20: 5 | AA20: 0 | AB20: 0 | AC20: 0 | AD20: 66.381 | AE20: Basna | AF20: Chhattisgarh | AG20: COD | AH20: 07AALCG0172B1Z0 | AI20: GOFPL2707100591 | AJ20: 28449601317134 | AL20: 46113.319 | AM20: 46113.481 | AN20: 46115.733 | AO20: 1 | AQ20: Yes | AR20: 2 | AS20: 6.638095 | AT20: Delivered
A21: APRIL_1_to_15_Orders | B21: 4 | C21: GOFPL | D21: GOTCHA FASHIONS PVT LTD_DL | E21: GOTCHA FASHIONS PRIVATE LIMITED-NF Mid Apr-26 Sales | F21: Fashion_GOFPL_042026_Sales_01-15 | G21: NYK-38385468-3479391 | H21: NYK-38385468-3479391-2-1 | I21: NYKF42435601 | J21: CHELV00000227 | K21: Chelvet Solid Lightly Padded Half Coverage Plunge Bra (36D) | L21: Chelvet | M21: 61089100 | N21: 1499 | O21: 1050 | P21: 1050 | Q21: 1050 | R21: 0 | S21: 449 | T21: 0 | U21: 0 | V21: 1050 | W21: 1050 | X21: 1000 | Y21: 50 | Z21: 5 | AA21: 0 | AB21: 0 | AC21: 0 | AD21: 50 | AE21: Jaipur | AF21: Rajasthan | AG21: Prepaid | AH21: 07AALCG0172B1Z0 | AI21: GOFPL2707100612 | AJ21: NKFP0000533379 | AK21: R2011711627NYK | AL21: 46124.825 | AM21: 46125.567 | AN21: 46127.494 | AO21: 1 | AQ21: Yes | AR21: 1 | AS21: 0 | AT21: Return
A22: APRIL_1_to_15_Orders | B22: 4 | C22: GOFPL | D22: GOTCHA FASHIONS PVT LTD_DL | E22: GOTCHA FASHIONS PRIVATE LIMITED-NF Mid Apr-26 Sales | F22: Fashion_GOFPL_042026_Sales_01-15 | G22: NYK-38130788-0594892 | H22: NYK-38130788-0594892-1-1 | I22: NYKF42144141 | J22: CHELV00002308 | K22: Chelvet Collared Full-Sleeve Shirt and Pyjama Burgundy (M) | L22: Chelvet | M22: 61091000 | N22: 4400 | O22: 2816 | P22: 2816 | Q22: 2816 | R22: 0 | S22: 1584 | T22: 0 | U22: 0 | V22: 2816 | W22: 2816 | X22: 2386.441 | Y22: 429.559 | Z22: 18 | AA22: 0 | AB22: 0 | AC22: 0 | AD22: 429.559 | AE22: Bangalore | AF22: Karnataka | AG22: COD | AH22: 09AALCG0172B1ZW | AL22: 46117.847 | AO22: 1 | AQ22: Yes | AR22: 3 | AS22: 0 | AT22: Cancelled
A23: APRIL_1_to_15_Orders | B23: 4 | C23: GOFPL | D23: GOTCHA FASHIONS PVT LTD_DL | E23: GOTCHA FASHIONS PRIVATE LIMITED-NF Mid Apr-26 Sales | F23: Fashion_GOFPL_042026_Sales_01-15 | G23: NYK-38142305-4246438 | H23: NYK-38142305-4246438-3-1 | I23: NYKF42157848 | J23: CHELV00001325 | K23: Chelvet Women Off White Satin Embroidered Nightdress (XL) | L23: Chelvet | M23: 62082200 | N23: 4299 | O23: 2881 | P23: 2881 | Q23: 2881 | R23: 0 | S23: 1418 | T23: 0 | U23: 0 | V23: 2881 | W23: 2881 | X23: 2441.525 | Y23: 439.475 | Z23: 18 | AA23: 0 | AB23: 0 | AC23: 0 | AD23: 439.475 | AE23: Chennai | AF23: Tamil Nadu | AG23: Prepaid | AH23: 09AALCG0172B1ZW | AI23: GOFPL2709100143 | AJ23: 28449602083785 | AL23: 46118.121 | AM23: 46118.618 | AN23: 46120.737 | AO23: 1 | AQ23: Yes | AR23: 1 | AS23: 12.207625 | AT23: Delivered
A24: APRIL_1_to_15_Orders | B24: 4 | C24: GOFPL | D24: GOTCHA FASHIONS PVT LTD_DL | E24: GOTCHA FASHIONS PRIVATE LIMITED-NF Mid Apr-26 Sales | F24: Fashion_GOFPL_042026_Sales_01-15 | G24: NYK-38323114-6441537 | H24: NYK-38323114-6441537-4-1 | I24: NYKF42363266 | J24: CHELV00001011 | K24: Chelvet Non-Wired Seamless Finish Plunge Bra (32B) | L24: Chelvet | M24: 62121000 | N24: 1849 | O24: 1295 | P24: 1202.95 | Q24: 1295 | R24: 0 | S24: 554 | T24: 92.050003 | U24: 0 | V24: 1295 | W24: 1295 | X24: 1233.333 | Y24: 61.667 | Z24: 5 | AA24: 0 | AB24: 0 | AC24: 0 | AD24: 61.667 | AE24: Nagaur | AF24: Rajasthan | AG24: Prepaid | AH24: 07AALCG0172B1Z0 | AL24: 46123.47 | AO24: 1 | AQ24: Yes | AR24: 1 | AS24: 0 | AT24: Not Shipped
A25: APRIL_1_to_15_Orders | B25: 4 | C25: GOFPL | D25: GOTCHA FASHIONS PVT LTD_DL | E25: GOTCHA FASHIONS PRIVATE LIMITED-NF Mid Apr-26 Sales | F25: Fashion_GOFPL_042026_Sales_01-15 | G25: NYK-38252658-2942706 | H25: NYK-38252658-2942706-1-1 | I25: NYKF42283181 | J25: CHELV00002389 | K25: Chelvet Black Non-Padded Non-Wired Lace Bra (32B) | L25: Chelvet | M25: 62121000 | N25: 1499 | O25: 900 | P25: 900 | Q25: 900 | R25: 0 | S25: 599 | T25: 0 | U25: 0 | V25: 900 | W25: 900 | X25: 857.143 | Y25: 42.857 | Z25: 5 | AA25: 0 | AB25: 0 | AC25: 0 | AD25: 42.857 | AE25: Himmatnagar | AF25: Gujarat | AG25: Prepaid | AH25: 09AALCG0172B1ZW | AI25: GOFPL2709100159 | AJ25: 28449602338736 | AL25: 46121.578 | AM25: 46122.65 | AN25: 46126.449 | AO25: 1 | AQ25: Yes | AR25: 1 | AS25: 4.285715 | AT25: Delivered
A26: APRIL_1_to_15_Orders | B26: 4 | C26: GOFPL | D26: GOTCHA FASHIONS PVT LTD_DL | E26: GOTCHA FASHIONS PRIVATE LIMITED-NF Mid Apr-26 Sales | F26: Fashion_GOFPL_042026_Sales_01-15 | G26: NYK-38055810-7290756 | H26: NYK-38055810-7290756-1-1 | I26: NYKF42145480 | J26: CHELV00002434 | K26: Chelvet Black Non-Padded Non-Wired Lace Bra (38B) | L26: Chelvet | M26: 62121000 | N26: 1499 | O26: 900 | P26: 900 | Q26: 900 | R26: 0 | S26: 599 | T26: 0 | U26: 0 | V26: 900 | W26: 900 | X26: 857.143 | Y26: 42.857 | Z26: 5 | AA26: 0 | AB26: 0 | AC26: 0 | AD26: 42.857 | AE26: Bangalore | AF26: Karnataka | AG26: Prepaid | AH26: 09AALCG0172B1ZW | AI26: GOFPL2709100152 | AJ26: 28449602082982 | AL26: 46115.726 | AM26: 46119.685 | AN26: 46121.664 | AO26: 1 | AQ26: Yes | AR26: 1 | AS26: 4.285715 | AT26: Delivered
A27: APRIL_1_to_15_Orders | B27: 4 | C27: GOFPL | D27: GOTCHA FASHIONS PVT LTD_DL | E27: GOTCHA FASHIONS PRIVATE LIMITED-NF Mid Apr-26 Sales | F27: Fashion_GOFPL_042026_Sales_01-15 | G27: NYK-38313689-9120998 | H27: NYK-38313689-9120998-5-1 | I27: NYKF42352757 | J27: CHELV00000212 | K27: Chelvet Lightly Padded Classic T-Shirt Bra (34B) | L27: Chelvet | M27: 61089100 | N27: 1899 | O27: 1406 | P27: 1406 | Q27: 1406 | R27: 0 | S27: 493 | T27: 0 | U27: 0 | V27: 1406 | W27: 1406 | X27: 1339.048 | Y27: 66.952 | Z27: 5 | AA27: 0 | AB27: 0 | AC27: 0 | AD27: 66.952 | AE27: Hyderabad | AF27: Telangana | AG27: COD | AH27: 07AALCG0172B1Z0 | AI27: GOFPL2707100609 | AJ27: 59695211752 | AL27: 46123.038 | AM27: 46123.685 | AN27: 46124.586 | AO27: 1 | AQ27: Yes | AR27: 1 | AS27: 6.69524 | AT27: Delivered
A28: APRIL_1_to_15_Orders | B28: 4 | C28: GOFPL | D28: GOTCHA FASHIONS PVT LTD_DL | E28: GOTCHA FASHIONS PRIVATE LIMITED-NF Mid Apr-26 Sales | F28: Fashion_GOFPL_042026_Sales_01-15 | G28: NYK-38485322-8493652 | H28: NYK-38485322-8493652-6-1 | I28: NYKF42551518 | J28: CHELV00000407 | K28: Chelvet Olive Ultra-Soft Lightly Padded Non-Wired Everyday Bra - Medium Coverage (32C) | L28: Chelvet | M28: 62121000 | N28: 1849 | O28: 1406 | P28: 1384.13 | Q28: 1406 | R28: 0 | S28: 443 | T28: 21.870001 | U28: 0 | V28: 1406 | W28: 1406 | X28: 1339.048 | Y28: 66.952 | Z28: 5 | AA28: 0 | AB28: 0 | AC28: 0 | AD28: 66.952 | AE28: Mumbai | AF28: Maharashtra | AG28: Prepaid | AH28: 07AALCG0172B1Z0 | AL28: 46127.429 | AO28: 1 | AQ28: Yes | AR28: 1 | AS28: 0 | AT28: Not Shipped
A29: APRIL_1_to_15_Orders | B29: 4 | C29: GOFPL | D29: GOTCHA FASHIONS PVT LTD_DL | E29: GOTCHA FASHIONS PRIVATE LIMITED-NF Mid Apr-26 Sales | F29: Fashion_GOFPL_042026_Sales_01-15 | G29: NYK-38025780-6136753 | H29: NYK-38025780-6136753-2-1 | I29: NYKF42025249 | J29: CHELV00002004 | K29: Chelvet Non-Padded Underwired Lace Bra and Brief (34B) | L29: Chelvet | M29: 62121000 | N29: 2999 | O29: 2400 | P29: 2400 | Q29: 2400 | R29: 0 | S29: 599 | T29: 0 | U29: 0 | V29: 2400 | W29: 2400 | X29: 2285.714 | Y29: 114.286 | Z29: 5 | AA29: 0 | AB29: 0 | AC29: 0 | AD29: 114.286 | AE29: Mumbai | AF29: Maharashtra | AG29: Prepaid | AH29: 09AALCG0172B1ZW | AI29: GOFPL2709100140 | AJ29: 28449609681854 | AL29: 46114.786 | AM29: 46115.622 | AN29: 46118.623 | AO29: 1 | AQ29: Yes | AR29: 1 | AS29: 11.42857 | AT29: Delivered
A30: APRIL_1_to_15_Orders | B30: 4 | C30: GOFPL | D30: GOTCHA FASHIONS PVT LTD_DL | E30: GOTCHA FASHIONS PRIVATE LIMITED-NF Mid Apr-26 Sales | F30: Fashion_GOFPL_042026_Sales_01-15 | G30: NYK-38325574-0275387 | H30: NYK-38325574-0275387-3-1 | I30: NYKF42366040 | J30: CHELV00002212 | K30: Chelvet Black Satin Cami, Pyjama and Robe (S) | L30: Chelvet | M30: 61091000 | N30: 5500 | O30: 5500 | P30: 5372.19 | Q30: 5500 | R30: 0 | S30: 0 | T30: 127.81 | U30: 0 | V30: 5500 | W30: 5500 | X30: 4661.017 | Y30: 838.983 | Z30: 18 | AA30: 0 | AB30: 0 | AC30: 0 | AD30: 838.983 | AE30: Vizianagaram | AF30: Andhra Pradesh | AG30: COD | AH30: 09AALCG0172B1ZW | AI30: GOFPL2709100166 | AJ30: 28449606073623 | AL30: 46123.515 | AM30: 46127.678 | AO30: 1 | AP30: Extra 15% off upto 280 on mov of 1800 - RB - Dynamic - 3 PV | AQ30: Yes | AR30: 1 | AS30: 0 | AT30: Shipped
A31: APRIL_1_to_15_Orders | B31: 4 | C31: GOFPL | D31: GOTCHA FASHIONS PVT LTD_DL | E31: GOTCHA FASHIONS PRIVATE LIMITED-NF Mid Apr-26 Sales | F31: Fashion_GOFPL_042026_Sales_01-15 | G31: NYK-38064984-4715797 | H31: NYK-38064984-4715797-1-1 | I31: NYKF42069133 | J31: CHELV00000011 | K31: Chelvet Women Full Coverage Lightly Padded Bra (38D) | L31: Chelvet | M31: 61089100 | N31: 2099 | O31: 1407 | P31: 1407 | Q31: 1407 | R31: 0 | S31: 692 | T31: 0 | U31: 0 | V31: 1407 | W31: 1407 | X31: 1340 | Y31: 67 | Z31: 5 | AA31: 0 | AB31: 0 | AC31: 0 | AD31: 67 | AE31: Kazhakkoottam | AF31: Kerala | AG31: Prepaid | AH31: 07AALCG0172B1Z0 | AI31: GOFPL2707100598 | AJ31: 28449609722255 | AK31: 28449612130163 | AL31: 46115.927 | AM31: 46116.498 | AN31: 46120.491 | AO31: 1 | AQ31: Yes | AR31: 1 | AS31: 0 | AT31: Return
A32: APRIL_1_to_15_Orders | B32: 4 | C32: GOFPL | D32: GOTCHA FASHIONS PVT LTD_DL | E32: GOTCHA FASHIONS PRIVATE LIMITED-NF Mid Apr-26 Sales | F32: Fashion_GOFPL_042026_Sales_01-15 | G32: NYK-38226464-3188365 | H32: NYK-38226464-3188365-2-1 | I32: NYKF42253368 | J32: CHELV00001655 | K32: Chelvet Pink Satin Shirt With Shorts (M) | L32: Chelvet | M32: 62082200 | N32: 2799 | O32: 2799 | P32: 2799 | Q32: 2799 | R32: 0 | S32: 0 | T32: 0 | U32: 0 | V32: 2799 | W32: 2799 | X32: 2372.034 | Y32: 426.966 | Z32: 18 | AA32: 0 | AB32: 0 | AC32: 0 | AD32: 426.966 | AE32: Gurugram | AF32: Haryana | AG32: COD | AH32: 09AALCG0172B1ZW | AI32: GOFPL2709100158 | AJ32: SF2188978318NYK | AL32: 46120.771 | AM32: 46121.657 | AN32: 46122.637 | AO32: 1 | AQ32: Yes | AR32: 1 | AS32: 11.86017 | AT32: Delivered
A33: APRIL_1_to_15_Orders | B33: 4 | C33: GOFPL | D33: GOTCHA FASHIONS PVT LTD_DL | E33: GOTCHA FASHIONS PRIVATE LIMITED-NF Mid Apr-26 Sales | F33: Fashion_GOFPL_042026_Sales_01-15 | G33: NYK-38151278-0783319 | H33: NYK-38151278-0783319-3-1 | I33: NYKF42167932 | J33: CHELV00000178 | K33: Chelvet Lightly Padded Classic T-Shirt Bra (32C) | L33: Chelvet | M33: 61089100 | N33: 1899 | O33: 1406 | P33: 1406 | Q33: 1406 | R33: 0 | S33: 493 | T33: 0 | U33: 0 | V33: 1406 | W33: 1406 | X33: 1339.048 | Y33: 66.952 | Z33: 5 | AA33: 0 | AB33: 0 | AC33: 0 | AD33: 66.952 | AE33: Jajpur | AF33: Orissa | AG33: Prepaid | AH33: 07AALCG0172B1Z0 | AI33: GOFPL2707100602 | AJ33: 28449602144663 | AL33: 46118.544 | AM33: 46119.513 | AN33: 46122.441 | AO33: 1 | AQ33: Yes | AR33: 2 | AS33: 6.69524 | AT33: Delivered
A34: APRIL_1_to_15_Orders | B34: 4 | C34: GOFPL | D34: GOTCHA FASHIONS PVT LTD_DL | E34: GOTCHA FASHIONS PRIVATE LIMITED-NF Mid Apr-26 Sales | F34: Fashion_GOFPL_042026_Sales_01-15 | G34: NYK-38316546-8288821 | H34: NYK-38316546-8288821-2-1 | I34: NYKF42355951 | J34: CHELV00002249 | K34: Chelvet Floral Strappy Nightdress and Full Sleeve Robe (L) | L34: Chelvet | M34: 61091000 | N34: 4950 | O34: 3168 | P34: 2949.09 | Q34: 3168 | R34: 0 | S34: 1782 | T34: 218.91 | U34: 0 | V34: 3168 | W34: 3168 | X34: 2684.746 | Y34: 483.254 | Z34: 18 | AA34: 241.627 | AB34: 241.627 | AC34: 0 | AD34: 0 | AE34: Noida | AF34: Uttar Pradesh | AG34: COD | AH34: 09AALCG0172B1ZW | AI34: GOFPL2709100165 | AJ34: SF2188981730NYK | AL34: 46123.26 | AM34: 46123.585 | AN34: 46125.603 | AO34: 1 | AQ34: Yes | AR34: 1 | AS34: 13.42373 | AT34: Delivered
A35: APRIL_1_to_15_Orders | B35: 4 | C35: GOFPL | D35: GOTCHA FASHIONS PVT LTD_DL | E35: GOTCHA FASHIONS PRIVATE LIMITED-NF Mid Apr-26 Sales | F35: Fashion_GOFPL_042026_Sales_01-15 | G35: NYK-38353054-2045424 | H35: NYK-38353054-2045424-1-1 | I35: NYKF42397848 | J35: CHELV00001143 | K35: Chelvet Non-Wired Medium Coverage T-Shirt Bra (32B) | L35: Chelvet | M35: 62121000 | N35: 1849 | O35: 1054 | P35: 1054 | Q35: 1054 | R35: 0 | S35: 795 | T35: 0 | U35: 0 | V35: 1054 | W35: 1054 | X35: 1003.81 | Y35: 50.19 | Z35: 5 | AA35: 0 | AB35: 0 | AC35: 0 | AD35: 50.19 | AE35: Indore | AF35: Madhya Pradesh | AG35: Prepaid | AH35: 07AALCG0172B1Z0 | AI35: GOFPL2707100611 | AJ35: 28449602582001 | AL35: 46123.998 | AM35: 46125.499 | AO35: 1 | AQ35: Yes | AR35: 1 | AS35: 0 | AT35: Shipped
A36: APRIL_1_to_15_Orders | B36: 4 | C36: GOFPL | D36: GOTCHA FASHIONS PVT LTD_DL | E36: GOTCHA FASHIONS PRIVATE LIMITED-NF Mid Apr-26 Sales | F36: Fashion_GOFPL_042026_Sales_01-15 | G36: NYK-38112834-8327464 | H36: NYK-38112834-8327464-2-1 | I36: NYKF42123624 | J36: CHELV00001692 | K36: Chelvet Pink Satin Shirt With Pyjama With Shorts (L) | L36: Chelvet | M36: 62082200 | N36: 3599 | O36: 3599 | P36: 3507.29 | Q36: 3599 | R36: 0 | S36: 0 | T36: 91.709999 | U36: 0 | V36: 3599 | W36: 3599 | X36: 3050 | Y36: 549 | Z36: 18 | AA36: 0 | AB36: 0 | AC36: 0 | AD36: 549 | AE36: Raipur | AF36: Chhattisgarh | AG36: COD | AH36: 09AALCG0172B1ZW | AI36: GOFPL2709100150 | AJ36: 28449601682033 | AL36: 46117.474 | AM36: 46118.618 | AN36: 46122.614 | AO36: 1 | AP36: Dynamic RB Paltform wide:Extra 10% off upto 270 on 1700 : 3 PV | AQ36: Yes | AR36: 3 | AS36: 15.25 | AT36: Delivered
A37: APRIL_1_to_15_Orders | B37: 4 | C37: GOFPL | D37: GOTCHA FASHIONS PVT LTD_DL | E37: GOTCHA FASHIONS PRIVATE LIMITED-NF Mid Apr-26 Sales | F37: Fashion_GOFPL_042026_Sales_01-15 | G37: NYK-38162061-4122460 | H37: NYK-38162061-4122460-2-1 | I37: NYKF42180205 | J37: CHELV00001898 | K37: Chelvet Seamless Hipster Panties Multi-Color (Pack of 2) (L) | L37: Chelvet | M37: 61082210 | N37: 1299 | O37: 689 | P37: 657.18 | Q37: 689 | R37: 0 | S37: 610 | T37: 31.82 | U37: 0 | V37: 689 | W37: 689 | X37: 656.19 | Y37: 32.81 | Z37: 5 | AA37: 0 | AB37: 0 | AC37: 0 | AD37: 32.81 | AE37: Ranchi | AF37: Jharkhand | AG37: Prepaid | AH37: 09AALCG0172B1ZW | AI37: GOFPL2709100157 | AJ37: 28449602168091 | AL37: 46118.814 | AM37: 46119.685 | AN37: 46124.405 | AO37: 1 | AQ37: Yes | AR37: 1 | AS37: 3.28095 | AT37: Delivered
A38: APRIL_1_to_15_Orders | B38: 4 | C38: GOFPL | D38: GOTCHA FASHIONS PVT LTD_DL | E38: GOTCHA FASHIONS PRIVATE LIMITED-NF Mid Apr-26 Sales | F38: Fashion_GOFPL_042026_Sales_01-15 | G38: NYK-38028258-2025293 | H38: NYK-38028258-2025293-3-1 | I38: NYKF42028172 | J38: CHELV00002218 | K38: Chelvet Pink Satin Cami, Pyjama and Robe (M) | L38: Chelvet | M38: 61091000 | N38: 5500 | O38: 3520 | P38: 3520 | Q38: 3520 | R38: 0 | S38: 1980 | T38: 0 | U38: 0 | V38: 3520 | W38: 3520 | X38: 2983.051 | Y38: 536.949 | Z38: 18 | AA38: 0 | AB38: 0 | AC38: 0 | AD38: 536.949 | AE38: Mumbai | AF38: Maharashtra | AG38: COD | AH38: 09AALCG0172B1ZW | AI38: GOFPL2709100139 | AJ38: 28449601465125 | AL38: 46114.854 | AM38: 46115.622 | AO38: 1 | AQ38: Yes | AR38: 1 | AS38: 0 | AT38: RTO
A39: APRIL_1_to_15_Orders | B39: 4 | C39: GOFPL | D39: GOTCHA FASHIONS PVT LTD_DL | E39: GOTCHA FASHIONS PRIVATE LIMITED-NF Mid Apr-26 Sales | F39: Fashion_GOFPL_042026_Sales_01-15 | G39: NYK-38098162-0351202 | H39: NYK-38098162-0351202-1-1 | I39: NYKF42106914 | J39: CHELV00001550 | K39: Chelvet Women Beige Seamless Padded Front-Closure Bra (XL) | L39: Chelvet | M39: 62121000 | N39: 2264 | O39: 1698 | P39: 1698 | Q39: 1698 | R39: 0 | S39: 566 | T39: 0 | U39: 0 | V39: 1698 | W39: 1698 | X39: 1617.143 | Y39: 80.857 | Z39: 5 | AA39: 0 | AB39: 0 | AC39: 0 | AD39: 80.857 | AE39: Vadodara | AF39: Gujarat | AG39: Prepaid | AH39: 09AALCG0172B1ZW | AI39: GOFPL2709100144 | AJ39: 28449602084054 | AL39: 46116.918 | AM39: 46119.685 | AN39: 46122.808 | AO39: 1 | AQ39: Yes | AR39: 1 | AS39: 8.085715 | AT39: Delivered
A40: APRIL_1_to_15_Orders | B40: 4 | C40: GOFPL | D40: GOTCHA FASHIONS PVT LTD_DL | E40: GOTCHA FASHIONS PRIVATE LIMITED-NF Mid Apr-26 Sales | F40: Fashion_GOFPL_042026_Sales_01-15 | G40: NYK-38030183-5823098 | H40: NYK-38030183-5823098-1-1 | I40: NYKF42030358 | J40: CHELV00001547 | K40: Chelvet Women Beige Seamless Padded Front-Closure Bra (S) | L40: Chelvet | M40: 62121000 | N40: 2264 | O40: 1698 | P40: 1698 | Q40: 1698 | R40: 0 | S40: 566 | T40: 0 | U40: 0 | V40: 1698 | W40: 1698 | X40: 1617.143 | Y40: 80.857 | Z40: 5 | AA40: 0 | AB40: 0 | AC40: 0 | AD40: 80.857 | AE40: Pune | AF40: Maharashtra | AG40: Prepaid | AH40: 09AALCG0172B1ZW | AL40: 46114.898 | AO40: 1 | AQ40: Yes | AR40: 1 | AS40: 0 | AT40: Cancelled
...

Sheet myntra
A1: sale_order_code | B1: order_number | C1: order_date | D1: packing_date | E1: invoice_number | F1: product_sku_code | G1: order_item_status | H1: promised_delivery_date | I1: actual_delivery_date | J1: return_date | K1: restocked_date | L1: return_type | M1: promised_settlement_date | N1: currency | O1: seller_paid_amount | P1: postpaid_amount | Q1: prepaid_amount | R1: mrp | S1: discount_amount | T1: shipping_case | U1: tax_rate | V1: igst_amount | W1: cgst_amount | X1: sgst_amount | Y1: tcs_igst_amt | Z1: tcs_sgst_amt | AA1: tcs_cgst_amt | AB1: minimum_commission | AC1: commission_pct | AD1: commission_total_amount | AE1: total_commission_plus_tcs_deduction_fw | AF1: logistics_deduction_fw | AG1: customer_paid_amt_fw | AH1: total_settlement_fw | AI1: amount_pending_settlement_fw | AJ1: prepaid_commission_deduction_fw | AK1: prepaid_logistics_deduction_fw | AL1: prepaid_payment_fw | AM1: postpaid_commission_deduction_fw | AN1: postpaid_logistics_deduction_fw | AO1: postpaid_payment_fw | AP1: settlement_date_prepaid_comm_deduction_fw | AQ1: settlement_date_prepaid_logistics_deduction_fw | AR1: settlement_date_prepaid_payment_fw | AS1: settlement_date_postpaid_comm_deduction_fw | AT1: settlement_date_postpaid_logistics_deduction_fw | AU1: settlement_date_postpaid_payment_fw | AV1: bank_utr_no_prepaid_comm_deduction_fw | AW1: bank_utr_no_prepaid_logistics_deduction_fw | AX1: bank_utr_no_prepaid_payment_fw | AY1: bank_utr_no_postpaid_comm_deduction_fw | AZ1: bank_utr_no_postpaid_logistics_deduction_fw | BA1: bank_utr_no_postpaid_payment_fw | BB1: total_commission_plus_tcs_deduction_rv | BC1: logistics_deduction_rv | BD1: customer_paid_amt_rv | BE1: total_settlement_rv | BF1: amount_pending_settlement_rv | BG1: prepaid_commission_deduction_rv | BH1: prepaid_logistics_deduction_rv | BI1: prepaid_payment_rv | BJ1: postpaid_commission_deduction_rv | BK1: postpaid_logistics_deduction_rv | BL1: postpaid_payment_rv | BM1: settlement_date_prepaid_comm_deduction_rv | BN1: settlement_date_prepaid_logistics_deduction_rv | BO1: settlement_date_prepaid_payment_rv | BP1: settlement_date_postpaid_comm_deduction_rv | BQ1: settlement_date_postpaid_logistics_deduction_rv | BR1: settlement_date_postpaid_payment_rv | BS1: bank_utr_no_prepaid_comm_deduction_rv | BT1: bank_utr_no_prepaid_logistics_deduction_rv | BU1: bank_utr_no_prepaid_payment_rv | BV1: bank_utr_no_postpaid_comm_deduction_rv | BW1: bank_utr_no_postpaid_logistics_deduction_rv | BX1: bank_utr_no_postpaid_payment_rv | BY1: courier_name | BZ1: e_commerce_portal_name | CA1: hsn | CB1: product_tax_category | CC1: payment_method | CD1: brand | CE1: gender | CF1: article_type | CG1: supply_type | CH1: is_try_and_buy | CI1: tracking_no | CJ1: customer_name | CK1: customer_pincode | CL1: customer_state | CM1: igst_rate | CN1: cgst_rate | CO1: sgst_rate | CP1: taxable_amount | CQ1: tcs_igst_rate | CR1: tcs_sgst_rate | CS1: tcs_cgst_rate | CT1: shipping_amount | CU1: gift_amount | CV1: cart_discount | CW1: coupon_discount | CX1: seller_gstn | CY1: seller_name | CZ1: seller_state_code | DA1: additional_amount | DB1: postpaid_amount_other | DC1: prepaid_amount_other | DD1: myntra_gstn | DE1: party_id_to | DF1: Item_Code | DG1: Item_Created_On | DH1: Item_Updated_On | DI1: Item_Status | DJ1: GRN_Number | DK1: GRN_Created | DL1: Vendor_Code | DM1: Facility | DN1: Item_Type_Name | DO1: _MRP | DP1: Item_Type_skuCode | DQ1: Vendor_skuCode | DR1: Unit_price_without_tax | DS1: Unit_price_with_tax | DT1: Rejection_Reason | DU1: Gate_Pass_No | DV1: Gate_Pass_Type | DW1: Gate_Pass_Status | DX1: Gate_Pass_Created | DY1: HSN_Code | DZ1: _Invoice_Number | EA1: _Invoice_Date | EB1: FOCI_PO_TYPE | EC1: PO_Code | ED1: PO_Created | EE1: Sale_Order_status | EF1: Myntra_Status_OGP | EG1: Vendor_Style_Code | EH1: ASN_code | EI1: ASN_created | EJ1: ASN_packed | EK1: ASN_picked | EL1: FOCI_supply_type | EM1: Total_Customer_Paid | EN1: commission_base_amount | EO1: commission_tax_amount | EP1: packed_id | EQ1: seller_order_id | ER1: return_id | ES1: item_id | ET1: return_status
A2: 100062098942 | B2: 1.3291408e+20 | C2: 2026-04-27T09:30:17.000+05:30 | D2: 46139.558 | E2: I0727GE000004876 | F2: CVETBRAA103717725 | G2: delivered | H2: 46144.479 | I2: 46143.775 | N2: INR | O2: 883 | P2: 0 | Q2: 882.99 | R2: 1849 | S2: 872 | T2: Inter-State | U2: 5 | V2: 42.05 | W2: 0 | X2: 0 | Y2: 4.20475 | Z2: 0 | AA2: 0 | AB2: 0 | AC2: 13.35 | AD2: 117.88 | BZ2: Myntra Designs Pvt Ltd | CA2: 62121000 | CB2: Apparel | CD2: Chelvet | CE2: Women | CF2: Bra | CG2: ON_HAND | CH2: FALSE | CI2: MYSP1394390734 | CJ2: 90c07133.382b.45ea.96e8.63a1892de4810HpFM8CVmf | CK2: 560034 | CL2: KA | CM2: 5 | CN2: 0 | CO2: 0 | CP2: 840.95 | CQ2: 0.5 | CR2: 0 | CS2: 0 | CT2: 0 | CU2: 0 | CW2: 0 | CX2: 07AALCG0172B1Z0 | CZ2: DL | DA2: 0 | DB2: 0 | DC2: 0 | DD2: 29AAECM9636P1ZJ | DE2: 27477 | EB2: PPMP | EL2: ON_HAND | EM2: 977.01 | EP2: 1000018121905 | EQ2: 3626c190-f207-4614-a06b-e62ed12ca6c5 | ES2: 11116828070
A3: 100046237953 | B3: 1.3282998e+20 | C3: 2026-04-17T15:53:52.000+05:30 | D3: 46129.667 | E3: I0927GE000000139 | F3: CVETBRAA127094138 | G3: reverse_in_transit | H3: 46134.479 | I3: 46135.069 | J3: 46135.086 | L3: return_refund | N3: INR | O3: 742 | P3: 0 | Q3: 742 | R3: 2199 | S3: 1363 | T3: Inter-State | U3: 5 | V3: 35.33 | W3: 0 | X3: 0 | Y3: 3.53335 | Z3: 0 | AA3: 0 | AB3: 0 | AC3: 14.29 | AD3: 106.032 | BZ3: Myntra Designs Pvt Ltd | CA3: 62121000 | CB3: Apparel | CD3: Chelvet | CE3: Women | CF3: Bra | CG3: ON_HAND | CH3: FALSE | CI3: MYSP1390016902 | CJ3: d67c8db3.7b7e.4e47.b779.d3dd19d0948d4YpKMinOEy | CK3: 400097 | CL3: MH | CM3: 5 | CN3: 0 | CO3: 0 | CP3: 706.67 | CQ3: 0.5 | CR3: 0 | CS3: 0 | CT3: 0 | CU3: 0 | CW3: 0 | CX3: 09AALCG0172B1ZW | CZ3: UP | DA3: 0 | DB3: 0 | DC3: 0 | DD3: 29AAECM9636P1ZJ | DE3: 27477 | EB3: PPMP | EL3: ON_HAND | EM3: 836 | EP3: 100046237953 | EQ3: 61edc745-b1dc-4b52-86d0-0fcca2aac121 | ES3: 11100966920 | ET3: DLS
A4: 100050606696 | B4: 1.3284962e+20 | C4: 2026-04-19T22:26:23.000+05:30 | D4: 46133.47 | E4: I0727GE000003975 | F4: CVETBRAA103682614 | G4: delivered | H4: 46139.354 | I4: 46139.684 | N4: INR | O4: 589 | P4: 0 | Q4: 589 | R4: 1499 | S4: 816 | T4: Inter-State | U4: 5 | V4: 28.05 | W4: 0 | X4: 0 | Y4: 2.80475 | Z4: 0 | AA4: 0 | AB4: 0 | AC4: 20.06 | AD4: 118.153 | BZ4: Myntra Designs Pvt Ltd | CA4: 62121000 | CB4: Apparel | CD4: Chelvet | CE4: Women | CF4: Bra | CG4: ON_HAND | CH4: FALSE | CI4: MYSP1391692628 | CJ4: 80e92566.58ba.4ee8.98c6.7581db0ff471N54UljOCg1 | CK4: 515004 | CL4: AP | CM4: 5 | CN4: 0 | CO4: 0 | CP4: 560.95 | CQ4: 0.5 | CR4: 0 | CS4: 0 | CT4: 0 | CU4: 0 | CW4: 0 | CX4: 07AALCG0172B1Z0 | CZ4: DL | DA4: 0 | DB4: 0 | DC4: 0 | DD4: 29AAECM9636P1ZJ | DE4: 27477 | EB4: PPMP | EL4: ON_HAND | EM4: 683 | EP4: 100050606696 | EQ4: e7d979c2-1e44-4002-a9d8-1bcc551fea9a | ES4: 11105335711
A5: 100045641471 | B5: 1.3282772e+20 | C5: 2026-04-17T09:37:33.000+05:30 | D5: 46129.432 | E5: I0927GE000000127 | F5: CVETNTST127223919 | G5: delivered | H5: 46133.479 | I5: 46133.776 | N5: INR | O5: 3294.01 | P5: 0 | Q5: 3294 | R5: 5500 | S5: 2000 | T5: Inter-State | U5: 18 | V5: 502.48 | W5: 0 | X5: 0 | Y5: 13.95765 | Z5: 0 | AA5: 0 | AB5: 0 | AC5: 17.7 | AD5: 583.038 | BZ5: Myntra Designs Pvt Ltd | CA5: 62082200 | CB5: Apparel | CD5: Chelvet | CE5: Women | CF5: Night suits | CG5: ON_HAND | CH5: FALSE | CI5: MYSP1389820286 | CJ5: 9bcec229.faed.4749.98fb.f858b5b65a3d5hb3fn65Wv | CK5: 248198 | CL5: UT | CM5: 18 | CN5: 0 | CO5: 0 | CP5: 2791.53 | CQ5: 0.5 | CR5: 0 | CS5: 0 | CT5: 0 | CU5: 0 | CW5: 0 | CX5: 09AALCG0172B1ZW | CZ5: UP | DA5: 0 | DB5: 0 | DC5: 0 | DD5: 29AAECM9636P1ZJ | DE5: 27477 | EB5: PPMP | EL5: ON_HAND | EM5: 3500.01 | EP5: 100045641471 | EQ5: 7860f2a7-4a08-4821-8923-9ef54a266cf4 | ES5: 11100370438
A6: 100057688280 | B6: 1.328908e+20 | C6: 2026-04-24T16:51:14.000+05:30 | D6: 46137.443 | E6: I0727GE000004556 | F6: CVETBRAA103646617 | G6: delivered | H6: 46141.479 | I6: 46141.714 | N6: INR | O6: 625 | P6: 0 | Q6: 625 | R6: 1499 | S6: 780 | T6: Inter-State | U6: 5 | V6: 29.76 | W6: 0 | X6: 0 | Y6: 2.9762 | Z6: 0 | AA6: 0 | AB6: 0 | AC6: 12.05 | AD6: 75.312 | BZ6: Myntra Designs Pvt Ltd | CA6: 62121000 | CB6: Apparel | CD6: Chelvet | CE6: Women | CF6: Bra | CG6: ON_HAND | CH6: FALSE | CI6: MYSP1393344595 | CJ6: e7438daf.b8f6.43f2.9c60.32ea9b29dd0917J2mkJM0N | CK6: 411008 | CL6: MH | CM6: 5 | CN6: 0 | CO6: 0 | CP6: 595.24 | CQ6: 0.5 | CR6: 0 | CS6: 0 | CT6: 0 | CU6: 0 | CW6: 0 | CX6: 07AALCG0172B1Z0 | CZ6: DL | DA6: 0 | DB6: 0 | DC6: 0 | DD6: 29AAECM9636P1ZJ | DE6: 27477 | EB6: PPMP | EL6: ON_HAND | EM6: 719 | EP6: 100057688280 | EQ6: 629d2633-0881-413e-a22b-2337640a6ec9 | ES6: 11112417349
A7: 100027429716 | B7: 1.3274546e+20 | C7: 2026-04-07T21:07:14.000+05:30 | D7: 46120.417 | E7: I0727GE000001551 | F7: CVETBRAA103705077 | G7: delivered | H7: 46124.479 | I7: 46123.753 | N7: INR | O7: 608 | P7: 0 | Q7: 608 | R7: 1849 | S7: 1147 | T7: Inter-State | U7: 5 | V7: 28.95 | W7: 0 | X7: 0 | Y7: 2.89525 | Z7: 0 | AA7: 0 | AB7: 0 | AC7: 10.3 | AD7: 62.624 | BZ7: Myntra Designs Pvt Ltd | CA7: 62121000 | CB7: Apparel | CD7: Chelvet | CE7: Women | CF7: Bra | CG7: ON_HAND | CH7: FALSE | CI7: MYSP1385237800 | CJ7: af012cee.7b87.4aa9.abb4.8b9e6c368838wTVmSLiGej | CK7: 411011 | CL7: MH | CM7: 5 | CN7: 0 | CO7: 0 | CP7: 579.05 | CQ7: 0.5 | CR7: 0 | CS7: 0 | CT7: 0 | CU7: 0 | CW7: 0 | CX7: 07AALCG0172B1Z0 | CZ7: DL | DA7: 0 | DB7: 0 | DC7: 0 | DD7: 29AAECM9636P1ZJ | DE7: 27477 | EB7: PPMP | EL7: ON_HAND | EM7: 702 | EP7: 100027429716 | EQ7: f7d5a0e8-d2a3-4405-9d18-03a2cdbbdf98 | ES7: 11082158650
A8: 100036528122 | B8: 1.3278629e+20 | C8: 2026-04-12T14:31:51.000+05:30 | D8: 46125.461 | E8: I0727GE000002474 | F8: CVETBRAA103722914 | G8: delivered | H8: 46129.479 | I8: 46130.025 | N8: INR | O8: 525 | P8: 0 | Q8: 525 | R8: 1999 | S8: 1380 | T8: Inter-State | U8: 5 | V8: 25 | W8: 0 | X8: 0 | Y8: 2.5 | Z8: 0 | AA8: 0 | AB8: 0 | AC8: 8.65 | AD8: 45.413 | BZ8: Myntra Designs Pvt Ltd | CA8: 62121000 | CB8: Apparel | CD8: Chelvet | CE8: Women | CF8: Bra | CG8: ON_HAND | CH8: FALSE | CI8: MYSP1387970834 | CJ8: 916d20ab.e348.4064.94ac.1b91b63cee68ovL07npyng | CK8: 560043 | CL8: KA | CM8: 5 | CN8: 0 | CO8: 0 | CP8: 500 | CQ8: 0.5 | CR8: 0 | CS8: 0 | CT8: 0 | CU8: 0 | CW8: 0 | CX8: 07AALCG0172B1Z0 | CZ8: DL | DA8: 0 | DB8: 0 | DC8: 0 | DD8: 29AAECM9636P1ZJ | DE8: 27477 | EB8: PPMP | EL8: ON_HAND | EM8: 619 | EP8: 100036528122 | EQ8: 7342fcb4-c5f2-4f53-bd2b-8c9eb19fd50b | ES8: 11091257077
A9: 100037450836 | B9: 1.3278906e+20 | C9: 2026-04-12T22:14:10.000+05:30 | D9: 46126.415 | E9: I0927GE000000103 | F9: CVETBRAA127094095 | G9: reverse_in_transit | H9: 46130.479 | L9: release_rto_refund | N9: INR | O9: 645 | P9: 0 | Q9: 645 | R9: 1999 | S9: 1260 | T9: Inter-State | U9: 5 | V9: 30.71 | W9: 0 | X9: 0 | Y9: 3.07145 | Z9: 0 | AA9: 0 | AB9: 0 | AC9: 14.04 | AD9: 90.558 | BZ9: Myntra Designs Pvt Ltd | CA9: 62121000 | CB9: Apparel | CD9: Chelvet | CE9: Women | CF9: Bra | CG9: ON_HAND | CH9: FALSE | CI9: MYSP1388414214 | CJ9: 9e0ed2fb.02e9.41ad.a516.3ad714ee62a1uctYnI4GUT | CK9: 411021 | CL9: MH | CM9: 5 | CN9: 0 | CO9: 0 | CP9: 614.29 | CQ9: 0.5 | CR9: 0 | CS9: 0 | CT9: 0 | CU9: 0 | CW9: 0 | CX9: 09AALCG0172B1ZW | CZ9: UP | DA9: 0 | DB9: 0 | DC9: 0 | DD9: 29AAECM9636P1ZJ | DE9: 27477 | EB9: PPMP | EL9: ON_HAND | EM9: 739 | EP9: 100037450836 | EQ9: 25ec7360-e465-419a-b8af-93ba7a568654 | ES9: 11092179791
A10: 100037219755 | B10: 1.327884e+20 | C10: 2026-04-12T20:24:37.000+05:30 | D10: 46125.464 | E10: I0727GE000002500 | F10: CVETBRAA103682605 | G10: delivered | H10: 46129.479 | I10: 46129.667 | N10: INR | O10: 535 | P10: 0 | Q10: 535 | R10: 1499 | S10: 870 | T10: Inter-State | U10: 5 | V10: 25.48 | W10: 0 | X10: 0 | Y10: 2.5476 | Z10: 0 | AA10: 0 | AB10: 0 | AC10: 11.88 | AD10: 63.558 | BZ10: Myntra Designs Pvt Ltd | CA10: 62121000 | CB10: Apparel | CD10: Chelvet | CE10: Women | CF10: Bra | CG10: ON_HAND | CH10: FALSE | CI10: MYEP1114324694 | CJ10: cab1b639.12d7.4a1b.9357.f13f0918cc74A7vLlAc5hi | CK10: 815301 | CL10: JH | CM10: 5 | CN10: 0 | CO10: 0 | CP10: 509.52 | CQ10: 0.5 | CR10: 0 | CS10: 0 | CT10: 0 | CU10: 0 | CW10: 0 | CX10: 07AALCG0172B1Z0 | CZ10: DL | DA10: 0 | DB10: 0 | DC10: 0 | DD10: 29AAECM9636P1ZJ | DE10: 27477 | EB10: PPMP | EL10: ON_HAND | EM10: 629 | EP10: 100037219755 | EQ10: d473029c-50c3-4c0b-ac95-c7cc01596278 | ES10: 11091948710
A11: 100031467610 | B11: 1.3276307e+20 | C11: 2026-04-09T22:01:59.000+05:30 | D11: 46122.44 | E11: I0927GE000000073 | F11: CVETBRAA127713179 | G11: delivered | H11: 46129.479 | I11: 46128.026 | N11: INR | O11: 998 | P11: 998 | Q11: 0 | R11: 2999 | S11: 1830 | T11: Inter-State | U11: 5 | V11: 47.52 | W11: 0 | X11: 0 | Y11: 4.7524 | Z11: 0 | AA11: 0 | AB11: 0 | AC11: 14.2 | AD11: 141.716 | BZ11: Myntra Designs Pvt Ltd | CA11: 62121000 | CB11: Apparel | CD11: Chelvet | CE11: Women | CF11: Bra | CG11: ON_HAND | CH11: FALSE | CI11: MYSC1282367654 | CJ11: a0a373c3.ea0f.495c.8a6a.d29ed96a3d576ftjMqPHHx | CK11: 190001 | CL11: JK | CM11: 5 | CN11: 0 | CO11: 0 | CP11: 950.48 | CQ11: 0.5 | CR11: 0 | CS11: 0 | CT11: 0 | CU11: 0 | CW11: 0 | CX11: 09AALCG0172B1ZW | CZ11: UP | DA11: 0 | DB11: 0 | DC11: 0 | DD11: 29AAECM9636P1ZJ | DE11: 27477 | EB11: PPMP | EL11: ON_HAND | EM11: 1169 | EP11: 1000009096790 | EQ11: 11fbd2da-3ef7-4682-b12b-8ff46799b138 | ES11: 11086196556
A12: 100014574204 | B12: 1.3269119e+20 | C12: 2026-04-01T14:21:54.000+05:30 | D12: 46114.429 | E12: I0727GE000000285 | F12: CVETBRAA103697034 | G12: reverse_in_transit | H12: 46120.958 | L12: release_rto_refund | N12: INR | O12: 622 | P12: 622 | Q12: 0 | R12: 1749 | S12: 1033 | T12: Inter-State | U12: 5 | V12: 29.62 | W12: 0 | X12: 0 | Y12: 2.9619 | Z12: 0 | AA12: 0 | AB12: 0 | AC12: 11.79 | AD12: 73.334 | BZ12: Myntra Designs Pvt Ltd | CA12: 62121000 | CB12: Apparel | CD12: Chelvet | CE12: Women | CF12: Bra | CG12: ON_HAND | CH12: FALSE | CI12: 5965570380431 | CJ12: e6c7ef34.85ea.4055.9bdc.0ef21197d8bbgO4fJOUarw | CK12: 272152 | CL12: UP | CM12: 5 | CN12: 0 | CO12: 0 | CP12: 592.38 | CQ12: 0.5 | CR12: 0 | CS12: 0 | CT12: 0 | CU12: 0 | CW12: 0 | CX12: 07AALCG0172B1Z0 | CZ12: DL | DA12: 0 | DB12: 0 | DC12: 0 | DD12: 29AAECM9636P1ZJ | DE12: 27477 | EB12: PPMP | EL12: ON_HAND | EM12: 716 | EP12: 100014574204 | EQ12: 32c8db63-01db-48d5-b5af-0dc5a40e2a3d | ES12: 11069303026
A13: 100047464456 | B13: 1.3283658e+20 | C13: 2026-04-18T10:13:13.000+05:30 | D13: 46130.483 | E13: I0727GE000003535 | F13: CVETBRAA103701214 | G13: delivered | H13: 46136.479 | I13: 46135.738 | N13: INR | O13: 873 | P13: 0 | Q13: 873 | R13: 1899 | S13: 932 | T13: Inter-State | U13: 5 | V13: 41.57 | W13: 0 | X13: 0 | Y13: 4.15715 | Z13: 0 | AA13: 0 | AB13: 0 | AC13: 12.64 | AD13: 110.347 | BZ13: Myntra Designs Pvt Ltd | CA13: 62121000 | CB13: Apparel | CD13: Chelvet | CE13: Women | CF13: Bra | CG13: ON_HAND | CH13: FALSE | CI13: MYEP1115037467 | CJ13: 7a82e088.cb9e.43aa.a102.ffd8667002beqLikx0ZIpk | CK13: 784010 | CL13: AS | CM13: 5 | CN13: 0 | CO13: 0 | CP13: 831.43 | CQ13: 0.5 | CR13: 0 | CS13: 0 | CT13: 0 | CU13: 0 | CW13: 0 | CX13: 07AALCG0172B1Z0 | CZ13: DL | DA13: 0 | DB13: 0 | DC13: 0 | DD13: 29AAECM9636P1ZJ | DE13: 27477 | EB13: PPMP | EL13: ON_HAND | EM13: 967 | EP13: 100047464456 | EQ13: 4998aa5a-bb7a-4bff-b72a-863a551aa12e | ES13: 11102193429
A14: 100059070276 | B14: 1.3289845e+20 | C14: 2026-04-25T14:05:21.000+05:30 | D14: 46137.765 | E14: I0927GE000000208 | F14: CVETNIDR118984921 | G14: delivered | H14: 46142.479 | I14: 46141.747 | N14: INR | O14: 1420 | P14: 1420 | Q14: 0 | R14: 4299 | S14: 2708 | T14: Intra-State | U14: 5 | V14: 0 | W14: 33.81 | X14: 33.81 | Y14: 0 | Z14: 3.38095 | AA14: 3.38095 | AB14: 0 | AC14: 11.82 | AD14: 167.844 | BZ14: Myntra Designs Pvt Ltd | CA14: 62082200 | CB14: Apparel | CD14: Chelvet | CE14: Women | CF14: Nightdress | CG14: ON_HAND | CH14: FALSE | CI14: MYSC1288017560 | CJ14: 1a9a081e.274c.492e.8e1e.2800df03eadaCp7oFDD0FV | CK14: 226001 | CL14: UP | CM14: 0 | CN14: 2.5 | CO14: 2.5 | CP14: 1352.38 | CQ14: 0 | CR14: 0.25 | CS14: 0.25 | CT14: 0 | CU14: 0 | CW14: 250 | CX14: 09AALCG0172B1ZW | CZ14: UP | DA14: 250 | DB14: 0 | DC14: 0 | DD14: 29AAECM9636P1ZJ | DE14: 27477 | EB14: PPMP | EL14: ON_HAND | EM14: 1591 | EP14: 100059070276 | EQ14: 61218dce-0a9c-4be8-b399-9f78e7909378 | ES14: 11113799369
A15: 100032479293 | B15: 1.3276849e+20 | C15: 2026-04-10T13:05:20.000+05:30 | D15: 46123.44 | E15: I0727GE000002324 | F15: CVETBRAA104595883 | G15: reverse_in_transit | H15: 46127.479 | L15: release_rto_refund | N15: INR | O15: 625 | P15: 625 | Q15: 0 | R15: 1499 | S15: 780 | T15: Inter-State | U15: 5 | V15: 29.76 | W15: 0 | X15: 0 | Y15: 2.9762 | Z15: 0 | AA15: 0 | AB15: 0 | AC15: 12.05 | AD15: 75.312 | BZ15: Myntra Designs Pvt Ltd | CA15: 62121000 | CB15: Apparel | CD15: Chelvet | CE15: Women | CF15: Bra | CG15: ON_HAND | CH15: FALSE | CI15: MYSC1282778426 | CJ15: 3942a201.875a.47ab.a621.81b709310f8eYOMlj6Ssga | CK15: 421204 | CL15: MH | CM15: 5 | CN15: 0 | CO15: 0 | CP15: 595.24 | CQ15: 0.5 | CR15: 0 | CS15: 0 | CT15: 0 | CU15: 0 | CW15: 0 | CX15: 07AALCG0172B1Z0 | CZ15: DL | DA15: 0 | DB15: 0 | DC15: 0 | DD15: 29AAECM9636P1ZJ | DE15: 27477 | EB15: PPMP | EL15: ON_HAND | EM15: 719 | EP15: 100032479293 | EQ15: 994550ad-22da-4084-b8f5-30386cfb1c8b | ES15: 11087208240
A16: 100054405440 | B16: 1.3287241e+20 | C16: 2026-04-22T13:44:45.000+05:30 | D16: 46135.449 | E16: I0727GE000004277 | F16: CVETBRAA104595888 | G16: reverse_in_transit | H16: 46136.75 | I16: 46136.78 | J16: 46138.807 | L16: return_refund | N16: INR | O16: 687 | P16: 687 | Q16: 0 | R16: 1499 | S16: 718 | T16: Inter-State | U16: 5 | V16: 32.71 | W16: 0 | X16: 0 | Y16: 3.27145 | Z16: 0 | AA16: 0 | AB16: 0 | AC16: 20.06 | AD16: 137.812 | BZ16: Myntra Designs Pvt Ltd | CA16: 62121000 | CB16: Apparel | CD16: Chelvet | CE16: Women | CF16: Bra | CG16: ON_HAND | CH16: FALSE | CI16: MYSC1287190087 | CJ16: b91b6040.d1bc.4249.821a.d5d934c52f8fcJYm4Apm1t | CK16: 122001 | CL16: HR | CM16: 5 | CN16: 0 | CO16: 0 | CP16: 654.29 | CQ16: 0.5 | CR16: 0 | CS16: 0 | CT16: 0 | CU16: 0 | CW16: 0 | CX16: 07AALCG0172B1Z0 | CZ16: DL | DA16: 0 | DB16: 0 | DC16: 0 | DD16: 29AAECM9636P1ZJ | DE16: 27477 | EB16: PPMP | EL16: ON_HAND | EM16: 781 | EP16: 100054405440 | EQ16: 4d78eb0b-760e-4038-b3f3-75edd6284c6b | ES16: 11109134474 | ET16: DLS
A17: 100030542238 | B17: 1.3275985e+20 | C17: 2026-04-09T13:06:07.000+05:30 | D17: 46121.731 | E17: I0927GE000000067 | F17: CVETBRAA120951084 | G17: reverse_in_transit | H17: 46126.479 | I17: 46126.683 | J17: 46126.779 | L17: return_refund | N17: INR | O17: 996 | P17: 0 | Q17: 996 | R17: 2540 | S17: 1373 | T17: Inter-State | U17: 5 | V17: 47.43 | W17: 0 | X17: 0 | Y17: 4.74285 | Z17: 0 | AA17: 0 | AB17: 0 | AC17: 14.21 | AD17: 141.532 | BZ17: Myntra Designs Pvt Ltd | CA17: 62121000 | CB17: Apparel | CD17: Chelvet | CE17: Women | CF17: Bra | CG17: ON_HAND | CH17: FALSE | CI17: MYSP1386074439 | CJ17: 78480c2c.0898.488c.98c0.e54e0d351cd64jRCKMhQkA | CK17: 560034 | CL17: KA | CM17: 5 | CN17: 0 | CO17: 0 | CP17: 948.57 | CQ17: 0.5 | CR17: 0 | CS17: 0 | CT17: 0 | CU17: 0 | CW17: 0 | CX17: 09AALCG0172B1ZW | CZ17: UP | DA17: 0 | DB17: 0 | DC17: 0 | DD17: 29AAECM9636P1ZJ | DE17: 27477 | EB17: PPMP | EL17: ON_HAND | EM17: 1167 | EP17: 1000008739819 | EQ17: 1ed20db0-ef6c-458a-b066-43bc3b3a5ade | ES17: 11085271182 | ET17: DLS
A18: 100066952585 | B18: 1.3294111e+20 | C18: 2026-04-30T12:35:06.000+05:30 | D18: 46142.533 | E18: I0727GE000005294 | F18: CVETBRAA103716925 | G18: delivered | H18: 46145.75 | I18: 46145.788 | N18: INR | O18: 883 | P18: 0 | Q18: 883 | R18: 1849 | S18: 872 | T18: Inter-State | U18: 5 | V18: 42.05 | W18: 0 | X18: 0 | Y18: 4.20475 | Z18: 0 | AA18: 0 | AB18: 0 | AC18: 13.35 | AD18: 117.88 | BZ18: Myntra Designs Pvt Ltd | CA18: 62121000 | CB18: Apparel | CD18: Chelvet | CE18: Women | CF18: Bra | CG18: ON_HAND | CH18: FALSE | CI18: MYSP1395621464 | CJ18: f954e58c.bb7a.43ab.9529.9a893b519df0AAMYFykzB2 | CK18: 500084 | CL18: TG | CM18: 5 | CN18: 0 | CO18: 0 | CP18: 840.95 | CQ18: 0.5 | CR18: 0 | CS18: 0 | CT18: 0 | CU18: 0 | CW18: 0 | CX18: 07AALCG0172B1Z0 | CZ18: DL | DA18: 0 | DB18: 0 | DC18: 0 | DD18: 29AAECM9636P1ZJ | DE18: 27477 | EB18: PPMP | EL18: ON_HAND | EM18: 977 | EP18: 1000019452711 | EQ18: 52e6effb-64ee-4480-a537-0ccad9c9d43d | ES18: 11121681773
A19: 100015723665 | B19: 1.3269461e+20 | C19: 2026-04-01T23:51:42.000+05:30 | D19: 46114.454 | E19: I0727GE000000349 | F19: CVETBRAA103723126 | G19: reverse_in_transit | H19: 46119.479 | L19: release_rto_refund | N19: INR | O19: 525 | P19: 0 | Q19: 525 | R19: 1999 | S19: 1380 | T19: Inter-State | U19: 5 | V19: 25 | W19: 0 | X19: 0 | Y19: 2.5 | Z19: 0 | AA19: 0 | AB19: 0 | AC19: 8.65 | AD19: 45.413 | BZ19: Myntra Designs Pvt Ltd | CA19: 62121000 | CB19: Apparel | CD19: Chelvet | CE19: Women | CF19: Bra | CG19: ON_HAND | CH19: FALSE | CI19: MYSP1382061742 | CJ19: 17aedc98.9888.42a4.a228.41e802aa7ac7BPCULLt03A | CK19: 751003 | CL19: OR | CM19: 5 | CN19: 0 | CO19: 0 | CP19: 500 | CQ19: 0.5 | CR19: 0 | CS19: 0 | CT19: 0 | CU19: 0 | CW19: 0 | CX19: 07AALCG0172B1Z0 | CZ19: DL | DA19: 0 | DB19: 0 | DC19: 0 | DD19: 29AAECM9636P1ZJ | DE19: 27477 | EB19: PPMP | EL19: ON_HAND | EM19: 619 | EP19: 100015723665 | EQ19: ec69582c-4b02-4079-838a-fb184c60a8c5 | ES19: 11070452493
A20: 100067391774 | B20: 1.3294307e+20 | C20: 2026-04-30T18:02:11.000+05:30 | D20: 46143.475 | E20: I0927GE000000261 | F20: CVETBRAA127713123 | G20: delivered | H20: 46147.479 | I20: 46146.733 | N20: INR | O20: 941 | P20: 0 | Q20: 941 | R20: 2099 | S20: 987 | T20: Inter-State | U20: 5 | V20: 44.81 | W20: 0 | X20: 0 | Y20: 4.48095 | Z20: 0 | AA20: 0 | AB20: 0 | AC20: 15.63 | AD20: 147.078 | BZ20: Myntra Designs Pvt Ltd | CA20: 62121000 | CB20: Apparel | CD20: Chelvet | CE20: Women | CF20: Bra | CG20: ON_HAND | CH20: FALSE | CI20: MYSP1395951530 | CJ20: 341dac55.52b9.4a4f.aa95.bb9aee5f29fdcacND8bemn | CK20: 313001 | CL20: RJ | CM20: 5 | CN20: 0 | CO20: 0 | CP20: 896.19 | CQ20: 0.5 | CR20: 0 | CS20: 0 | CT20: 0 | CU20: 0 | CW20: 0 | CX20: 09AALCG0172B1ZW | CZ20: UP | DA20: 0 | DB20: 0 | DC20: 0 | DD20: 29AAECM9636P1ZJ | DE20: 27477 | EB20: PPMP | EL20: ON_HAND | EM20: 1112 | EP20: 100067391774 | EQ20: 8d75e203-54ce-4856-be13-2742c07e52f3 | ES20: 11122120964
A21: 100053547722 | B21: 1.328667e+20 | C21: 2026-04-21T21:53:06.000+05:30 | D21: 46134.43 | E21: I0927GE000000174 | F21: CVETBRAA127713160 | G21: delivered | H21: 46135.75 | I21: 46136.006 | N21: INR | O21: 1148 | P21: 0 | Q21: 1148 | R21: 2999 | S21: 1680 | T21: Inter-State | U21: 5 | V21: 54.67 | W21: 0 | X21: 0 | Y21: 5.46665 | Z21: 0 | AA21: 0 | AB21: 0 | AC21: 23.6 | AD21: 270.928 | BZ21: Myntra Designs Pvt Ltd | CA21: 62121000 | CB21: Apparel | CD21: Chelvet | CE21: Women | CF21: Bra | CG21: ON_HAND | CH21: FALSE | CI21: MYSP1392070016 | CJ21: f89fba87.205e.4aed.949c.92f3fabe8ba9YZAmdB4TgL | CK21: 122003 | CL21: HR | CM21: 5 | CN21: 0 | CO21: 0 | CP21: 1093.33 | CQ21: 0.5 | CR21: 0 | CS21: 0 | CT21: 0 | CU21: 0 | CW21: 0 | CX21: 09AALCG0172B1ZW | CZ21: UP | DA21: 0 | DB21: 0 | DC21: 0 | DD21: 29AAECM9636P1ZJ | DE21: 27477 | EB21: PPMP | EL21: ON_HAND | EM21: 1319 | EP21: 100053547722 | EQ21: fe5468f5-d346-4c51-be40-eea156d65cad | ES21: 11108276749
A22: 100061903517 | B22: 1.3291128e+20 | C22: 2026-04-27T01:44:01.000+05:30 | D22: 46139.389 | E22: I0927GE000000209 | F22: CVETBRAA127431550 | G22: delivered | H22: 46140.75 | I22: 46140.941 | N22: INR | O22: 1569 | P22: 0 | Q22: 1569 | R22: 2599 | S22: 859 | T22: Inter-State | U22: 5 | V22: 74.71 | W22: 0 | X22: 0 | Y22: 7.47145 | Z22: 0 | AA22: 0 | AB22: 0 | AC22: 18.65 | AD22: 292.619 | BZ22: Myntra Designs Pvt Ltd | CA22: 62121000 | CB22: Apparel | CD22: Chelvet | CE22: Women | CF22: Bra | CG22: ON_HAND | CH22: FALSE | CI22: MYSP1394148095 | CJ22: dcced7ad.d01f.47d9.800f.c131b639cea1tTdzmUrMYM | CK22: 122012 | CL22: HR | CM22: 5 | CN22: 0 | CO22: 0 | CP22: 1494.29 | CQ22: 0.5 | CR22: 0 | CS22: 0 | CT22: 0 | CU22: 0 | CW22: 0 | CX22: 09AALCG0172B1ZW | CZ22: UP | DA22: 0 | DB22: 0 | DC22: 0 | DD22: 29AAECM9636P1ZJ | DE22: 27477 | EB22: PPMP | EL22: ON_HAND | EM22: 1740 | EP22: 100061903517 | EQ22: 5fe91dc5-b1ac-4d07-a3f3-08f715639609 | ES22: 11116632642
